Workbook

Sheet Dashboard
A1: DASHBOARD LAPORAN KEUANGAN
A2: SPPG Battuwinangun - Program Pemenuhan Gizi
A3: Periode: | B3: =TEXT(Pengaturan!B3,"dd mmm yyyy")&" s/d "&TEXT(Pengaturan!B4,"dd mmm yyyy") -> 01 Sep 2025 s/d 12 Sep 2025
A5: TOTAL DANA ANGGARAN | B5: TOTAL DIPAKAI | C5: TOTAL SISA DANA | D5: % PENYERAPAN | N5: Terpakai | O5: =IFERROR(B30,0) -> 342069931
A6: =Pengaturan!B10 -> 432670000 | B6: =SUM('Rekap Harian'!$F$6:$F$36)+SUM('Rekap Harian'!$I$6:$I$36) -> 342069931 | C6: =A6-B6 -> 90600069 | D6: =IF(A6=0,0,B6/A6) -> 0.79060238 | N6: Sisa | O6: =IFERROR(MAX(0,B31),0) -> 90600069
A8: A. PENGELUARAN BAHAN PANGAN | N8: Surplus | O8: =IFERROR(B44,0) -> 89391050
A9: Rata-Rata Pengeluaran Bahan Pangan / Hari | B9: =IFERROR(B14/Pengaturan!B5,0) -> 18449453 | N9: Defisit | O9: =IFERROR(ABS(B45),0) -> 64607481
A10: Pengeluaran Bahan Pangan Seharusnya / Hari | B10: =Pengaturan!B13 -> 28234000
A11: Selisih Pengeluaran Bahan Pangan / Hari | B11: =B10-B9 -> 9784547.4
A13: Dana Total Bahan Pangan | B13: =Pengaturan!B8 -> 282340000
A14: Penggunaan Dana Pangan | B14: =SUM('Rekap Harian'!$F$6:$F$36) -> 221393431
A15: Sisa Dana Pangan | B15: =B13-B14 -> 60946569
A16: % Penggunaan Dana Pangan | B16: =IF(B13=0,0,B14/B13) -> 0.78413767
A18: B. PENGELUARAN OPERASIONAL
A19: Rata-Rata Pengeluaran Operasional / Hari | B19: =IFERROR(B24/Pengaturan!B5,0) -> 10056375
A20: Pengeluaran Operasional Seharusnya / Hari | B20: =Pengaturan!B14 -> 12527500
A21: Selisih Pengeluaran Operasional / Hari | B21: =B20-B19 -> 2471125
A23: Dana Total Operasional | B23: =Pengaturan!B9 -> 150330000
A24: Penggunaan Dana Operasional | B24: =SUM('Rekap Harian'!$I$6:$I$36) -> 120676500
A25: Sisa Dana Operasional | B25: =B23-B24 -> 29653500
A26: % Penggunaan Dana Operasional | B26: =IF(B23=0,0,B24/B23) -> 0.80274396
A28: C. RINGKASAN TOTAL
A29: Total Dana Anggaran | B29: =B13+B23 -> 432670000
A30: Total Penggunaan Dana | B30: =B14+B24 -> 342069931
A31: Total Sisa Dana | B31: =B29-B30 -> 90600069
A32: % Penyerapan Anggaran | B32: =IF(B29=0,0,B30/B29) -> 0.79060238
A34: Rata-Rata Total Pengeluaran / Hari | B34: =B9+B19 -> 28505828
A35: Pagu Total / Hari (Seharusnya) | B35: =Pengaturan!B15 -> 40761500
A36: Selisih Total / Hari | B36: =B35-B34 -> 12255672 | C36: (positif = hemat)
A38: D. ANALISIS SURPLUS/DEFISIT
A39: Jumlah Hari SURPLUS (hemat) | B39: =COUNTIF('Rekap Harian'!N6:N36,"SURPLUS") -> 7
A40: Jumlah Hari DEFISIT (melewati pagu) | B40: =COUNTIF('Rekap Harian'!N6:N36,"DEFISIT") -> 2
A41: Jumlah Hari AMAN (pas pagu) | B41: =COUNTIF('Rekap Harian'!N6:N36,"AMAN") -> 3
A42: Jumlah Hari Belum Input | B42: =COUNTIF('Rekap Harian'!N6:N36,"BELUM") -> 0
A44: Total Akumulasi Surplus | B44: =SUMIF('Rekap Harian'!M6:M36,">0") -> 89391050
A45: Total Akumulasi Defisit | B45: =SUMIF('Rekap Harian'!M6:M36,"<0") -> -64607481
A46: Net Surplus/Defisit | B46: =B44+B45 -> 24783569
A47: % Surplus Total (dari Total Pagu) | B47: =IFERROR(B46/SUM('Rekap Harian'!$K$6:$K$36),0) -> 0
A48: Pengeluaran Tertinggi/Hari | B48: =MAX('Rekap Harian'!L6:L36) -> 103026181
A49: Pengeluaran Terendah/Hari | B49: =IFERROR(_xludf.MINIFS('Rekap Harian'!L6:L36,'Rekap Harian'!L6:L36,">0"),0) -> 0
...

Sheet Rekap Harian
A1: REKAP HARIAN PENGELUARAN
A2: Input aktual pangan (kolom F) & operasional (kolom I) setiap hari. Sisanya otomatis.
A3: Periode: | B3: =TEXT(Pengaturan!B3,"dd mmm yyyy")&" s/d "&TEXT(Pengaturan!B4,"dd mmm yyyy") -> 01 Sep 2025 s/d 12 Sep 2025
A5: No | B5: Tanggal | C5: Hari | D5: Mg Ke | E5: Pagu Pangan | F5: Aktual Pangan | G5: Selisih Pangan | H5: Pagu Operasional | I5: Aktual Operasional | J5: Selisih Operasional | K5: Total Pagu | L5: Total Aktual | M5: Surplus/Defisit | N5: Status | O5: Status Defisit | P5: Status Ops
A6: 1 | B6: =IF(Pengaturan!$B$3+0>Pengaturan!$B$4,"",Pengaturan!$B$3+0) -> 45901 | C6: =IF(B6="","",TEXT(B6,"dddd")) -> Senin | D6: =IF(B6="","",INT((B6-Pengaturan!$B$3)/7)+1) -> 1 | E6: =IFERROR(VLOOKUP(B6,'Pagu Harian'!$A$4:$D$40,2,FALSE),Pengaturan!$B$13) -> 28234000 | F6: 31728300 | G6: =IF(B6="",0,E6-IF(F6="",0,F6)) -> -3494300 | H6: =IFERROR(VLOOKUP(B6,'Pagu Harian'!$A$4:$D$40,3,FALSE),Pengaturan!$B$14) -> 12527500 | I6: =5656000+5720000 -> 11376000 | J6: =IF(B6="",0,H6-IF(I6="",0,I6)) -> 1151500 | K6: =E6+H6 -> 40761500 | L6: =IF(F6="",0,F6)+IF(I6="",0,I6) -> 43104300 | M6: =K6-L6 -> -2342800 | N6: =IF(B6="","",IF(AND(F6="",I6=""),"BELUM",IF(M6>0,"SURPLUS",IF(M6<0,"DEFISIT","AMAN")))) -> DEFISIT | O6: Pembayaran Sewa
A7: 2 | B7: =IF(Pengaturan!$B$3+1>Pengaturan!$B$4,"",Pengaturan!$B$3+1) -> 45902 | C7: =IF(B7="","",TEXT(B7,"dddd")) -> Selasa | D7: =IF(B7="","",INT((B7-Pengaturan!$B$3)/7)+1) -> 1 | E7: =IFERROR(VLOOKUP(B7,'Pagu Harian'!$A$4:$D$40,2,FALSE),Pengaturan!$B$13) -> 28234000 | F7: 29861200 | G7: =IF(B7="",0,E7-IF(F7="",0,F7)) -> -1627200 | H7: =IFERROR(VLOOKUP(B7,'Pagu Harian'!$A$4:$D$40,3,FALSE),Pengaturan!$B$14) -> 12527500 | I7: 1033500 | J7: =IF(B7="",0,H7-IF(I7="",0,I7)) -> 11494000 | K7: =E7+H7 -> 40761500 | L7: =IF(F7="",0,F7)+IF(I7="",0,I7) -> 30894700 | M7: =K7-L7 -> 9866800 | N7: =IF(B7="","",IF(AND(F7="",I7=""),"BELUM",IF(M7>0,"SURPLUS",IF(M7<0,"DEFISIT","AMAN")))) -> SURPLUS | O7: -
A8: 3 | B8: =IF(Pengaturan!$B$3+2>Pengaturan!$B$4,"",Pengaturan!$B$3+2) -> 45903 | C8: =IF(B8="","",TEXT(B8,"dddd")) -> Rabu | D8: =IF(B8="","",INT((B8-Pengaturan!$B$3)/7)+1) -> 1 | E8: =IFERROR(VLOOKUP(B8,'Pagu Harian'!$A$4:$D$40,2,FALSE),Pengaturan!$B$13) -> 28234000 | F8: 27381000 | G8: =IF(B8="",0,E8-IF(F8="",0,F8)) -> 853000 | H8: =IFERROR(VLOOKUP(B8,'Pagu Harian'!$A$4:$D$40,3,FALSE),Pengaturan!$B$14) -> 12527500 | I8: 2768000 | J8: =IF(B8="",0,H8-IF(I8="",0,I8)) -> 9759500 | K8: =E8+H8 -> 40761500 | L8: =IF(F8="",0,F8)+IF(I8="",0,I8) -> 30149000 | M8: =K8-L8 -> 10612500 | N8: =IF(B8="","",IF(AND(F8="",I8=""),"BELUM",IF(M8>0,"SURPLUS",IF(M8<0,"DEFISIT","AMAN")))) -> SURPLUS | O8: -
A9: 4 | B9: =IF(Pengaturan!$B$3+3>Pengaturan!$B$4,"",Pengaturan!$B$3+3) -> 45904 | C9: =IF(B9="","",TEXT(B9,"dddd")) -> Kamis | D9: =IF(B9="","",INT((B9-Pengaturan!$B$3)/7)+1) -> 1 | E9: =IFERROR(VLOOKUP(B9,'Pagu Harian'!$A$4:$D$40,2,FALSE),Pengaturan!$B$13) -> 28234000 | F9: 20791000 | G9: =IF(B9="",0,E9-IF(F9="",0,F9)) -> 7443000 | H9: =IFERROR(VLOOKUP(B9,'Pagu Harian'!$A$4:$D$40,3,FALSE),Pengaturan!$B$14) -> 12527500 | I9: =17720000+530000 -> 18250000 | J9: =IF(B9="",0,H9-IF(I9="",0,I9)) -> -5722500 | K9: =E9+H9 -> 40761500 | L9: =IF(F9="",0,F9)+IF(I9="",0,I9) -> 39041000 | M9: =K9-L9 -> 1720500 | N9: =IF(B9="","",IF(AND(F9="",I9=""),"BELUM",IF(M9>0,"SURPLUS",IF(M9<0,"DEFISIT","AMAN")))) -> SURPLUS | O9: Pembayaran Sewa
A10: 5 | B10: =IF(Pengaturan!$B$3+4>Pengaturan!$B$4,"",Pengaturan!$B$3+4) -> 45905 | C10: =IF(B10="","",TEXT(B10,"dddd")) -> Jumat | D10: =IF(B10="","",INT((B10-Pengaturan!$B$3)/7)+1) -> 1 | E10: 0 | F10: 0 | G10: 0 | H10: 0 | I10: 0 | J10: 0 | K10: 0 | L10: =IF(F10="",0,F10)+IF(I10="",0,I10) -> 0 | M10: 0 | N10: =IF(B10="","",IF(AND(F10="",I10=""),"BELUM",IF(M10>0,"SURPLUS",IF(M10<0,"DEFISIT","AMAN")))) -> AMAN | P10: Libur
A11: 6 | B11: =IF(Pengaturan!$B$3+5>Pengaturan!$B$4,"",Pengaturan!$B$3+5) -> 45906 | C11: =IF(B11="","",TEXT(B11,"dddd")) -> Sabtu | D11: =IF(B11="","",INT((B11-Pengaturan!$B$3)/7)+1) -> 1 | E11: 0 | F11: 0 | G11: 0 | H11: 0 | I11: 0 | J11: 0 | K11: 0 | L11: =IF(F11="",0,F11)+IF(I11="",0,I11) -> 0 | M11: 0 | N11: =IF(B11="","",IF(AND(F11="",I11=""),"BELUM",IF(M11>0,"SURPLUS",IF(M11<0,"DEFISIT","AMAN")))) -> AMAN | P11: Libur
A12: 7 | B12: =IF(Pengaturan!$B$3+6>Pengaturan!$B$4,"",Pengaturan!$B$3+6) -> 45907 | C12: =IF(B12="","",TEXT(B12,"dddd")) -> Minggu | D12: =IF(B12="","",INT((B12-Pengaturan!$B$3)/7)+1) -> 1 | E12: 0 | F12: 0 | G12: 0 | H12: 0 | I12: 0 | J12: 0 | K12: 0 | L12: =IF(F12="",0,F12)+IF(I12="",0,I12) -> 0 | M12: 0 | N12: =IF(B12="","",IF(AND(F12="",I12=""),"BELUM",IF(M12>0,"SURPLUS",IF(M12<0,"DEFISIT","AMAN")))) -> AMAN | P12: Libur
A13: 8 | B13: =IF(Pengaturan!$B$3+7>Pengaturan!$B$4,"",Pengaturan!$B$3+7) -> 45908 | C13: =IF(B13="","",TEXT(B13,"dddd")) -> Senin | D13: =IF(B13="","",INT((B13-Pengaturan!$B$3)/7)+1) -> 2 | E13: =IFERROR(VLOOKUP(B13,'Pagu Harian'!$A$4:$D$40,2,FALSE),Pengaturan!$B$13) -> 28234000 | F13: 23935050 | G13: =IF(B13="",0,E13-IF(F13="",0,F13)) -> 4298950 | H13: =IFERROR(VLOOKUP(B13,'Pagu Harian'!$A$4:$D$40,3,FALSE),Pengaturan!$B$14) -> 12527500 | I13: 5534000 | J13: =IF(B13="",0,H13-IF(I13="",0,I13)) -> 6993500 | K13: =E13+H13 -> 40761500 | L13: =IF(F13="",0,F13)+IF(I13="",0,I13) -> 29469050 | M13: =K13-L13 -> 11292450 | N13: =IF(B13="","",IF(AND(F13="",I13=""),"BELUM",IF(M13>0,"SURPLUS",IF(M13<0,"DEFISIT","AMAN")))) -> SURPLUS
A14: 9 | B14: =IF(Pengaturan!$B$3+8>Pengaturan!$B$4,"",Pengaturan!$B$3+8) -> 45909 | C14: =IF(B14="","",TEXT(B14,"dddd")) -> Selasa | D14: =IF(B14="","",INT((B14-Pengaturan!$B$3)/7)+1) -> 2 | E14: =IFERROR(VLOOKUP(B14,'Pagu Harian'!$A$4:$D$40,2,FALSE),Pengaturan!$B$13) -> 28234000 | F14: 22762300 | G14: =IF(B14="",0,E14-IF(F14="",0,F14)) -> 5471700 | H14: =IFERROR(VLOOKUP(B14,'Pagu Harian'!$A$4:$D$40,3,FALSE),Pengaturan!$B$14) -> 12527500 | I14: 0 | J14: =IF(B14="",0,H14-IF(I14="",0,I14)) -> 12527500 | K14: =E14+H14 -> 40761500 | L14: =IF(F14="",0,F14)+IF(I14="",0,I14) -> 22762300 | M14: =K14-L14 -> 17999200 | N14: =IF(B14="","",IF(AND(F14="",I14=""),"BELUM",IF(M14>0,"SURPLUS",IF(M14<0,"DEFISIT","AMAN")))) -> SURPLUS
A15: 10 | B15: =IF(Pengaturan!$B$3+9>Pengaturan!$B$4,"",Pengaturan!$B$3+9) -> 45910 | C15: =IF(B15="","",TEXT(B15,"dddd")) -> Rabu | D15: =IF(B15="","",INT((B15-Pengaturan!$B$3)/7)+1) -> 2 | E15: =IFERROR(VLOOKUP(B15,'Pagu Harian'!$A$4:$D$40,2,FALSE),Pengaturan!$B$13) -> 28234000 | F15: 16132300 | G15: =IF(B15="",0,E15-IF(F15="",0,F15)) -> 12101700 | H15: =IFERROR(VLOOKUP(B15,'Pagu Harian'!$A$4:$D$40,3,FALSE),Pengaturan!$B$14) -> 12527500 | I15: 1820000 | J15: =IF(B15="",0,H15-IF(I15="",0,I15)) -> 10707500 | K15: =E15+H15 -> 40761500 | L15: =IF(F15="",0,F15)+IF(I15="",0,I15) -> 17952300 | M15: =K15-L15 -> 22809200 | N15: =IF(B15="","",IF(AND(F15="",I15=""),"BELUM",IF(M15>0,"SURPLUS",IF(M15<0,"DEFISIT","AMAN")))) -> SURPLUS
A16: 11 | B16: =IF(Pengaturan!$B$3+10>Pengaturan!$B$4,"",Pengaturan!$B$3+10) -> 45911 | C16: =IF(B16="","",TEXT(B16,"dddd")) -> Kamis | D16: =IF(B16="","",INT((B16-Pengaturan!$B$3)/7)+1) -> 2 | E16: =IFERROR(VLOOKUP(B16,'Pagu Harian'!$A$4:$D$40,2,FALSE),Pengaturan!$B$13) -> 28234000 | F16: 23274600 | G16: =IF(B16="",0,E16-IF(F16="",0,F16)) -> 4959400 | H16: =IFERROR(VLOOKUP(B16,'Pagu Harian'!$A$4:$D$40,3,FALSE),Pengaturan!$B$14) -> 12527500 | I16: 2396500 | J16: =IF(B16="",0,H16-IF(I16="",0,I16)) -> 10131000 | K16: =E16+H16 -> 40761500 | L16: =IF(F16="",0,F16)+IF(I16="",0,I16) -> 25671100 | M16: =K16-L16 -> 15090400 | N16: =IF(B16="","",IF(AND(F16="",I16=""),"BELUM",IF(M16>0,"SURPLUS",IF(M16<0,"DEFISIT","AMAN")))) -> SURPLUS
A17: 12 | B17: =IF(Pengaturan!$B$3+11>Pengaturan!$B$4,"",Pengaturan!$B$3+11) -> 45912 | C17: =IF(B17="","",TEXT(B17,"dddd")) -> Jumat | D17: =IF(B17="","",INT((B17-Pengaturan!$B$3)/7)+1) -> 2 | E17: =IFERROR(VLOOKUP(B17,'Pagu Harian'!$A$4:$D$40,2,FALSE),Pengaturan!$B$13) -> 28234000 | F17: 25527681 | G17: =IF(B17="",0,E17-IF(F17="",0,F17)) -> 2706319 | H17: =IFERROR(VLOOKUP(B17,'Pagu Harian'!$A$4:$D$40,3,FALSE),Pengaturan!$B$14) -> 12527500 | I17: =2738500+30090000+44670000 -> 77498500 | J17: =IF(B17="",0,H17-IF(I17="",0,I17)) -> -64971000 | K17: =E17+H17 -> 40761500 | L17: =IF(F17="",0,F17)+IF(I17="",0,I17) -> 103026181 | M17: =K17-L17 -> -62264681 | N17: =IF(B17="","",IF(AND(F17="",I17=""),"BELUM",IF(M17>0,"SURPLUS",IF(M17<0,"DEFISIT","AMAN")))) -> DEFISIT | O17: Pembayaran Sewa dan Gaji Relawan
A18: 13 | B18: =IF(Pengaturan!$B$3+12>Pengaturan!$B$4,"",Pengaturan!$B$3+12) | C18: =IF(B18="","",TEXT(B18,"dddd")) | D18: =IF(B18="","",INT((B18-Pengaturan!$B$3)/7)+1) | E18: =IFERROR(VLOOKUP(B18,'Pagu Harian'!$A$4:$D$40,2,FALSE),Pengaturan!$B$13) | G18: =IF(B18="",0,E18-IF(F18="",0,F18)) -> 0 | H18: =IFERROR(VLOOKUP(B18,'Pagu Harian'!$A$4:$D$40,3,FALSE),Pengaturan!$B$14) | J18: =IF(B18="",0,H18-IF(I18="",0,I18)) -> 0 | K18: =E18+H18 -> #VALUE! | L18: =IF(F18="",0,F18)+IF(I18="",0,I18) -> 0 | M18: =K18-L18 -> #VALUE! | N18: =IF(B18="","",IF(AND(F18="",I18=""),"BELUM",IF(M18>0,"SURPLUS",IF(M18<0,"DEFISIT","AMAN"))))
A19: 14 | B19: =IF(Pengaturan!$B$3+13>Pengaturan!$B$4,"",Pengaturan!$B$3+13) | C19: =IF(B19="","",TEXT(B19,"dddd")) | D19: =IF(B19="","",INT((B19-Pengaturan!$B$3)/7)+1) | E19: =IFERROR(VLOOKUP(B19,'Pagu Harian'!$A$4:$D$40,2,FALSE),Pengaturan!$B$13) | G19: =IF(B19="",0,E19-IF(F19="",0,F19)) -> 0 | H19: =IFERROR(VLOOKUP(B19,'Pagu Harian'!$A$4:$D$40,3,FALSE),Pengaturan!$B$14) | J19: =IF(B19="",0,H19-IF(I19="",0,I19)) -> 0 | K19: =E19+H19 -> #VALUE! | L19: =IF(F19="",0,F19)+IF(I19="",0,I19) -> 0 | M19: =K19-L19 -> #VALUE! | N19: =IF(B19="","",IF(AND(F19="",I19=""),"BELUM",IF(M19>0,"SURPLUS",IF(M19<0,"DEFISIT","AMAN"))))
A20: 15 | B20: =IF(Pengaturan!$B$3+14>Pengaturan!$B$4,"",Pengaturan!$B$3+14) | C20: =IF(B20="","",TEXT(B20,"dddd")) | D20: =IF(B20="","",INT((B20-Pengaturan!$B$3)/7)+1) | E20: =IFERROR(VLOOKUP(B20,'Pagu Harian'!$A$4:$D$40,2,FALSE),Pengaturan!$B$13) | G20: =IF(B20="",0,E20-IF(F20="",0,F20)) -> 0 | H20: =IFERROR(VLOOKUP(B20,'Pagu Harian'!$A$4:$D$40,3,FALSE),Pengaturan!$B$14) | J20: =IF(B20="",0,H20-IF(I20="",0,I20)) -> 0 | K20: =E20+H20 -> #VALUE! | L20: =IF(F20="",0,F20)+IF(I20="",0,I20) -> 0 | M20: =K20-L20 -> #VALUE! | N20: =IF(B20="","",IF(AND(F20="",I20=""),"BELUM",IF(M20>0,"SURPLUS",IF(M20<0,"DEFISIT","AMAN"))))
A21: 16 | B21: =IF(Pengaturan!$B$3+15>Pengaturan!$B$4,"",Pengaturan!$B$3+15) | C21: =IF(B21="","",TEXT(B21,"dddd")) | D21: =IF(B21="","",INT((B21-Pengaturan!$B$3)/7)+1) | E21: =IFERROR(VLOOKUP(B21,'Pagu Harian'!$A$4:$D$40,2,FALSE),Pengaturan!$B$13) | G21: =IF(B21="",0,E21-IF(F21="",0,F21)) -> 0 | H21: =IFERROR(VLOOKUP(B21,'Pagu Harian'!$A$4:$D$40,3,FALSE),Pengaturan!$B$14) | J21: =IF(B21="",0,H21-IF(I21="",0,I21)) -> 0 | K21: =E21+H21 -> #VALUE! | L21: =IF(F21="",0,F21)+IF(I21="",0,I21) -> 0 | M21: =K21-L21 -> #VALUE! | N21: =IF(B21="","",IF(AND(F21="",I21=""),"BELUM",IF(M21>0,"SURPLUS",IF(M21<0,"DEFISIT","AMAN"))))
A22: 17 | B22: =IF(Pengaturan!$B$3+16>Pengaturan!$B$4,"",Pengaturan!$B$3+16) | C22: =IF(B22="","",TEXT(B22,"dddd")) | D22: =IF(B22="","",INT((B22-Pengaturan!$B$3)/7)+1) | E22: =IFERROR(VLOOKUP(B22,'Pagu Harian'!$A$4:$D$40,2,FALSE),Pengaturan!$B$13) | G22: =IF(B22="",0,E22-IF(F22="",0,F22)) -> 0 | H22: =IFERROR(VLOOKUP(B22,'Pagu Harian'!$A$4:$D$40,3,FALSE),Pengaturan!$B$14) | J22: =IF(B22="",0,H22-IF(I22="",0,I22)) -> 0 | K22: =E22+H22 -> #VALUE! | L22: =IF(F22="",0,F22)+IF(I22="",0,I22) -> 0 | M22: =K22-L22 -> #VALUE! | N22: =IF(B22="","",IF(AND(F22="",I22=""),"BELUM",IF(M22>0,"SURPLUS",IF(M22<0,"DEFISIT","AMAN"))))
A23: 18 | B23: =IF(Pengaturan!$B$3+17>Pengaturan!$B$4,"",Pengaturan!$B$3+17) | C23: =IF(B23="","",TEXT(B23,"dddd")) | D23: =IF(B23="","",INT((B23-Pengaturan!$B$3)/7)+1) | E23: =IFERROR(VLOOKUP(B23,'Pagu Harian'!$A$4:$D$40,2,FALSE),Pengaturan!$B$13) | G23: =IF(B23="",0,E23-IF(F23="",0,F23)) -> 0 | H23: =IFERROR(VLOOKUP(B23,'Pagu Harian'!$A$4:$D$40,3,FALSE),Pengaturan!$B$14) | J23: =IF(B23="",0,H23-IF(I23="",0,I23)) -> 0 | K23: =E23+H23 -> #VALUE! | L23: =IF(F23="",0,F23)+IF(I23="",0,I23) -> 0 | M23: =K23-L23 -> #VALUE! | N23: =IF(B23="","",IF(AND(F23="",I23=""),"BELUM",IF(M23>0,"SURPLUS",IF(M23<0,"DEFISIT","AMAN"))))
A24: 19 | B24: =IF(Pengaturan!$B$3+18>Pengaturan!$B$4,"",Pengaturan!$B$3+18) | C24: =IF(B24="","",TEXT(B24,"dddd")) | D24: =IF(B24="","",INT((B24-Pengaturan!$B$3)/7)+1) | E24: =IFERROR(VLOOKUP(B24,'Pagu Harian'!$A$4:$D$40,2,FALSE),Pengaturan!$B$13) | G24: =IF(B24="",0,E24-IF(F24="",0,F24)) -> 0 | H24: =IFERROR(VLOOKUP(B24,'Pagu Harian'!$A$4:$D$40,3,FALSE),Pengaturan!$B$14) | J24: =IF(B24="",0,H24-IF(I24="",0,I24)) -> 0 | K24: =E24+H24 -> #VALUE! | L24: =IF(F24="",0,F24)+IF(I24="",0,I24) -> 0 | M24: =K24-L24 -> #VALUE! | N24: =IF(B24="","",IF(AND(F24="",I24=""),"BELUM",IF(M24>0,"SURPLUS",IF(M24<0,"DEFISIT","AMAN"))))
A25: 20 | B25: =IF(Pengaturan!$B$3+19>Pengaturan!$B$4,"",Pengaturan!$B$3+19) | C25: =IF(B25="","",TEXT(B25,"dddd")) | D25: =IF(B25="","",INT((B25-Pengaturan!$B$3)/7)+1) | E25: =IFERROR(VLOOKUP(B25,'Pagu Harian'!$A$4:$D$40,2,FALSE),Pengaturan!$B$13) | G25: =IF(B25="",0,E25-IF(F25="",0,F25)) -> 0 | H25: =IFERROR(VLOOKUP(B25,'Pagu Harian'!$A$4:$D$40,3,FALSE),Pengaturan!$B$14) | J25: =IF(B25="",0,H25-IF(I25="",0,I25)) -> 0 | K25: =E25+H25 -> #VALUE! | L25: =IF(F25="",0,F25)+IF(I25="",0,I25) -> 0 | M25: =K25-L25 -> #VALUE! | N25: =IF(B25="","",IF(AND(F25="",I25=""),"BELUM",IF(M25>0,"SURPLUS",IF(M25<0,"DEFISIT","AMAN"))))
A26: 21 | B26: =IF(Pengaturan!$B$3+20>Pengaturan!$B$4,"",Pengaturan!$B$3+20) | C26: =IF(B26="","",TEXT(B26,"dddd")) | D26: =IF(B26="","",INT((B26-Pengaturan!$B$3)/7)+1) | E26: =IFERROR(VLOOKUP(B26,'Pagu Harian'!$A$4:$D$40,2,FALSE),Pengaturan!$B$13) | G26: =IF(B26="",0,E26-IF(F26="",0,F26)) -> 0 | H26: =IFERROR(VLOOKUP(B26,'Pagu Harian'!$A$4:$D$40,3,FALSE),Pengaturan!$B$14) | J26: =IF(B26="",0,H26-IF(I26="",0,I26)) -> 0 | K26: =E26+H26 -> #VALUE! | L26: =IF(F26="",0,F26)+IF(I26="",0,I26) -> 0 | M26: =K26-L26 -> #VALUE! | N26: =IF(B26="","",IF(AND(F26="",I26=""),"BELUM",IF(M26>0,"SURPLUS",IF(M26<0,"DEFISIT","AMAN"))))
A27: 22 | B27: =IF(Pengaturan!$B$3+21>Pengaturan!$B$4,"",Pengaturan!$B$3+21) | C27: =IF(B27="","",TEXT(B27,"dddd")) | D27: =IF(B27="","",INT((B27-Pengaturan!$B$3)/7)+1) | E27: =IFERROR(VLOOKUP(B27,'Pagu Harian'!$A$4:$D$40,2,FALSE),Pengaturan!$B$13) | G27: =IF(B27="",0,E27-IF(F27="",0,F27)) -> 0 | H27: =IFERROR(VLOOKUP(B27,'Pagu Harian'!$A$4:$D$40,3,FALSE),Pengaturan!$B$14) | J27: =IF(B27="",0,H27-IF(I27="",0,I27)) -> 0 | K27: =E27+H27 -> #VALUE! | L27: =IF(F27="",0,F27)+IF(I27="",0,I27) -> 0 | M27: =K27-L27 -> #VALUE! | N27: =IF(B27="","",IF(AND(F27="",I27=""),"BELUM",IF(M27>0,"SURPLUS",IF(M27<0,"DEFISIT","AMAN"))))
A28: 23 | B28: =IF(Pengaturan!$B$3+22>Pengaturan!$B$4,"",Pengaturan!$B$3+22) | C28: =IF(B28="","",TEXT(B28,"dddd")) | D28: =IF(B28="","",INT((B28-Pengaturan!$B$3)/7)+1) | E28: =IFERROR(VLOOKUP(B28,'Pagu Harian'!$A$4:$D$40,2,FALSE),Pengaturan!$B$13) | G28: =IF(B28="",0,E28-IF(F28="",0,F28)) -> 0 | H28: =IFERROR(VLOOKUP(B28,'Pagu Harian'!$A$4:$D$40,3,FALSE),Pengaturan!$B$14) | J28: =IF(B28="",0,H28-IF(I28="",0,I28)) -> 0 | K28: =E28+H28 -> #VALUE! | L28: =IF(F28="",0,F28)+IF(I28="",0,I28) -> 0 | M28: =K28-L28 -> #VALUE! | N28: =IF(B28="","",IF(AND(F28="",I28=""),"BELUM",IF(M28>0,"SURPLUS",IF(M28<0,"DEFISIT","AMAN"))))
A29: 24 | B29: =IF(Pengaturan!$B$3+23>Pengaturan!$B$4,"",Pengaturan!$B$3+23) | C29: =IF(B29="","",TEXT(B29,"dddd")) | D29: =IF(B29="","",INT((B29-Pengaturan!$B$3)/7)+1) | E29: =IFERROR(VLOOKUP(B29,'Pagu Harian'!$A$4:$D$40,2,FALSE),Pengaturan!$B$13) | G29: =IF(B29="",0,E29-IF(F29="",0,F29)) -> 0 | H29: =IFERROR(VLOOKUP(B29,'Pagu Harian'!$A$4:$D$40,3,FALSE),Pengaturan!$B$14) | J29: =IF(B29="",0,H29-IF(I29="",0,I29)) -> 0 | K29: =E29+H29 -> #VALUE! | L29: =IF(F29="",0,F29)+IF(I29="",0,I29) -> 0 | M29: =K29-L29 -> #VALUE! | N29: =IF(B29="","",IF(AND(F29="",I29=""),"BELUM",IF(M29>0,"SURPLUS",IF(M29<0,"DEFISIT","AMAN"))))
A30: 25 | B30: =IF(Pengaturan!$B$3+24>Pengaturan!$B$4,"",Pengaturan!$B$3+24) | C30: =IF(B30="","",TEXT(B30,"dddd")) | D30: =IF(B30="","",INT((B30-Pengaturan!$B$3)/7)+1) | E30: =IFERROR(VLOOKUP(B30,'Pagu Harian'!$A$4:$D$40,2,FALSE),Pengaturan!$B$13) | G30: =IF(B30="",0,E30-IF(F30="",0,F30)) -> 0 | H30: =IFERROR(VLOOKUP(B30,'Pagu Harian'!$A$4:$D$40,3,FALSE),Pengaturan!$B$14) | J30: =IF(B30="",0,H30-IF(I30="",0,I30)) -> 0 | K30: =E30+H30 -> #VALUE! | L30: =IF(F30="",0,F30)+IF(I30="",0,I30) -> 0 | M30: =K30-L30 -> #VALUE! | N30: =IF(B30="","",IF(AND(F30="",I30=""),"BELUM",IF(M30>0,"SURPLUS",IF(M30<0,"DEFISIT","AMAN"))))
A31: 26 | B31: =IF(Pengaturan!$B$3+25>Pengaturan!$B$4,"",Pengaturan!$B$3+25) | C31: =IF(B31="","",TEXT(B31,"dddd")) | D31: =IF(B31="","",INT((B31-Pengaturan!$B$3)/7)+1) | E31: =IFERROR(VLOOKUP(B31,'Pagu Harian'!$A$4:$D$40,2,FALSE),Pengaturan!$B$13) | G31: =IF(B31="",0,E31-IF(F31="",0,F31)) -> 0 | H31: =IFERROR(VLOOKUP(B31,'Pagu Harian'!$A$4:$D$40,3,FALSE),Pengaturan!$B$14) | J31: =IF(B31="",0,H31-IF(I31="",0,I31)) -> 0 | K31: =E31+H31 -> #VALUE! | L31: =IF(F31="",0,F31)+IF(I31="",0,I31) -> 0 | M31: =K31-L31 -> #VALUE! | N31: =IF(B31="","",IF(AND(F31="",I31=""),"BELUM",IF(M31>0,"SURPLUS",IF(M31<0,"DEFISIT","AMAN"))))
A32: 27 | B32: =IF(Pengaturan!$B$3+26>Pengaturan!$B$4,"",Pengaturan!$B$3+26) | C32: =IF(B32="","",TEXT(B32,"dddd")) | D32: =IF(B32="","",INT((B32-Pengaturan!$B$3)/7)+1) | E32: =IFERROR(VLOOKUP(B32,'Pagu Harian'!$A$4:$D$40,2,FALSE),Pengaturan!$B$13) | G32: =IF(B32="",0,E32-IF(F32="",0,F32)) -> 0 | H32: =IFERROR(VLOOKUP(B32,'Pagu Harian'!$A$4:$D$40,3,FALSE),Pengaturan!$B$14) | J32: =IF(B32="",0,H32-IF(I32="",0,I32)) -> 0 | K32: =E32+H32 -> #VALUE! | L32: =IF(F32="",0,F32)+IF(I32="",0,I32) -> 0 | M32: =K32-L32 -> #VALUE! | N32: =IF(B32="","",IF(AND(F32="",I32=""),"BELUM",IF(M32>0,"SURPLUS",IF(M32<0,"DEFISIT","AMAN"))))
A33: 28 | B33: =IF(Pengaturan!$B$3+27>Pengaturan!$B$4,"",Pengaturan!$B$3+27) | C33: =IF(B33="","",TEXT(B33,"dddd")) | D33: =IF(B33="","",INT((B33-Pengaturan!$B$3)/7)+1) | E33: =IFERROR(VLOOKUP(B33,'Pagu Harian'!$A$4:$D$40,2,FALSE),Pengaturan!$B$13) | G33: =IF(B33="",0,E33-IF(F33="",0,F33)) -> 0 | H33: =IFERROR(VLOOKUP(B33,'Pagu Harian'!$A$4:$D$40,3,FALSE),Pengaturan!$B$14) | J33: =IF(B33="",0,H33-IF(I33="",0,I33)) -> 0 | K33: =E33+H33 -> #VALUE! | L33: =IF(F33="",0,F33)+IF(I33="",0,I33) -> 0 | M33: =K33-L33 -> #VALUE! | N33: =IF(B33="","",IF(AND(F33="",I33=""),"BELUM",IF(M33>0,"SURPLUS",IF(M33<0,"DEFISIT","AMAN"))))
A34: 29 | B34: =IF(Pengaturan!$B$3+28>Pengaturan!$B$4,"",Pengaturan!$B$3+28) | C34: =IF(B34="","",TEXT(B34,"dddd")) | D34: =IF(B34="","",INT((B34-Pengaturan!$B$3)/7)+1) | E34: =IFERROR(VLOOKUP(B34,'Pagu Harian'!$A$4:$D$40,2,FALSE),Pengaturan!$B$13) | G34: =IF(B34="",0,E34-IF(F34="",0,F34)) -> 0 | H34: =IFERROR(VLOOKUP(B34,'Pagu Harian'!$A$4:$D$40,3,FALSE),Pengaturan!$B$14) | J34: =IF(B34="",0,H34-IF(I34="",0,I34)) -> 0 | K34: =E34+H34 -> #VALUE! | L34: =IF(F34="",0,F34)+IF(I34="",0,I34) -> 0 | M34: =K34-L34 -> #VALUE! | N34: =IF(B34="","",IF(AND(F34="",I34=""),"BELUM",IF(M34>0,"SURPLUS",IF(M34<0,"DEFISIT","AMAN"))))
A35: 30 | B35: =IF(Pengaturan!$B$3+29>Pengaturan!$B$4,"",Pengaturan!$B$3+29) | C35: =IF(B35="","",TEXT(B35,"dddd")) | D35: =IF(B35="","",INT((B35-Pengaturan!$B$3)/7)+1) | E35: =IFERROR(VLOOKUP(B35,'Pagu Harian'!$A$4:$D$40,2,FALSE),Pengaturan!$B$13) | G35: =IF(B35="",0,E35-IF(F35="",0,F35)) -> 0 | H35: =IFERROR(VLOOKUP(B35,'Pagu Harian'!$A$4:$D$40,3,FALSE),Pengaturan!$B$14) | J35: =IF(B35="",0,H35-IF(I35="",0,I35)) -> 0 | K35: =E35+H35 -> #VALUE! | L35: =IF(F35="",0,F35)+IF(I35="",0,I35) -> 0 | M35: =K35-L35 -> #VALUE! | N35: =IF(B35="","",IF(AND(F35="",I35=""),"BELUM",IF(M35>0,"SURPLUS",IF(M35<0,"DEFISIT","AMAN"))))
A36: 31 | B36: =IF(Pengaturan!$B$3+30>Pengaturan!$B$4,"",Pengaturan!$B$3+30) | C36: =IF(B36="","",TEXT(B36,"dddd")) | D36: =IF(B36="","",INT((B36-Pengaturan!$B$3)/7)+1) | E36: =IFERROR(VLOOKUP(B36,'Pagu Harian'!$A$4:$D$40,2,FALSE),Pengaturan!$B$13) | G36: =IF(B36="",0,E36-IF(F36="",0,F36)) -> 0 | H36: =IFERROR(VLOOKUP(B36,'Pagu Harian'!$A$4:$D$40,3,FALSE),Pengaturan!$B$14) | J36: =IF(B36="",0,H36-IF(I36="",0,I36)) -> 0 | K36: =E36+H36 -> #VALUE! | L36: =IF(F36="",0,F36)+IF(I36="",0,I36) -> 0 | M36: =K36-L36 -> #VALUE! | N36: =IF(B36="","",IF(AND(F36="",I36=""),"BELUM",IF(M36>0,"SURPLUS",IF(M36<0,"DEFISIT","AMAN"))))
B38: TOTAL | E38: =SUM(E6:E36) -> 254106000 | F38: =SUM(F6:F36) -> 221393431 | G38: =SUM(G6:G36) -> 32712569 | H38: =SUM(H6:H36) -> 112747500 | I38: =SUM(I6:I36) -> 120676500 | J38: =SUM(J6:J36) -> -7929000 | K38: =SUM(K6:K36) -> #VALUE! | L38: =SUM(L6:L36) -> 342069931 | M38: =SUM(M6:M36) -> #VALUE!
B39: RATA-RATA/HARI | E39: =IFERROR(AVERAGEIF(B6:B36,"<>",E6:E36),0) -> 21175500 | F39: =IFERROR(AVERAGEIF(F6:F36,">0"),0) -> 24599270 | G39: =IFERROR(AVERAGEIF(B6:B36,"<>",G6:G36),0) -> 1055244.2 | H39: =IFERROR(AVERAGEIF(B6:B36,"<>",H6:H36),0) -> 9395625 | I39: =IFERROR(AVERAGEIF(I6:I36,">0"),0) -> 15084562 | J39: =IFERROR(AVERAGEIF(B6:B36,"<>",J6:J36),0) -> -255774.19 | K39: =IFERROR(AVERAGEIF(B6:B36,"<>",K6:K36),0) -> 0 | L39: =IFERROR(AVERAGEIF(L6:L36,">0"),0) -> 38007770 | M39: =IFERROR(AVERAGEIF(B6:B36,"<>",M6:M36),0) -> 0

Sheet Rekap Mingguan
A1: REKAP MINGGUAN PENGELUARAN
A2: Agregasi mingguan otomatis. Surplus = hemat, Defisit = boros
A3: Minggu Ke | B3: Periode | C3: Pagu Pangan | D3: Aktual Pangan | E3: Selisih Pangan | F3: Pagu Operasional | G3: Aktual Operasional | H3: Selisih Operasional | I3: Total Pagu | J3: Total Aktual | K3: Surplus/Defisit | L3: Status
A4: 1 | B4: =IF(Pengaturan!$B$3+0>Pengaturan!$B$4,"",TEXT(Pengaturan!$B$3+0,"dd mmm")&" - "&TEXT(MIN(Pengaturan!$B$3+6,Pengaturan!$B$4),"dd mmm")) -> 01 Sep - 07 Sep | C4: =SUMIF('Rekap Harian'!$D$6:$D$36,A4,'Rekap Harian'!$E$6:$E$36) -> 112936000 | D4: =SUMIF('Rekap Harian'!$D$6:$D$36,A4,'Rekap Harian'!$F$6:$F$36) -> 109761500 | E4: =C4-D4 -> 3174500 | F4: =SUMIF('Rekap Harian'!$D$6:$D$36,A4,'Rekap Harian'!$H$6:$H$36) -> 50110000 | G4: =SUMIF('Rekap Harian'!$D$6:$D$36,A4,'Rekap Harian'!$I$6:$I$36) -> 33427500 | H4: =F4-G4 -> 16682500 | I4: =C4+F4 -> 163046000 | J4: =D4+G4 -> 143189000 | K4: =I4-J4 -> 19857000 | L4: =IF(I4=0,"",IF(K4>0,"SURPLUS",IF(K4<0,"DEFISIT","AMAN"))) -> SURPLUS
A5: 2 | B5: =IF(Pengaturan!$B$3+7>Pengaturan!$B$4,"",TEXT(Pengaturan!$B$3+7,"dd mmm")&" - "&TEXT(MIN(Pengaturan!$B$3+13,Pengaturan!$B$4),"dd mmm")) -> 08 Sep - 12 Sep | C5: =SUMIF('Rekap Harian'!$D$6:$D$36,A5,'Rekap Harian'!$E$6:$E$36) -> 141170000 | D5: =SUMIF('Rekap Harian'!$D$6:$D$36,A5,'Rekap Harian'!$F$6:$F$36) -> 111631931 | E5: =C5-D5 -> 29538069 | F5: =SUMIF('Rekap Harian'!$D$6:$D$36,A5,'Rekap Harian'!$H$6:$H$36) -> 62637500 | G5: =SUMIF('Rekap Harian'!$D$6:$D$36,A5,'Rekap Harian'!$I$6:$I$36) -> 87249000 | H5: =F5-G5 -> -24611500 | I5: =C5+F5 -> 203807500 | J5: =D5+G5 -> 198880931 | K5: =I5-J5 -> 4926569 | L5: =IF(I5=0,"",IF(K5>0,"SURPLUS",IF(K5<0,"DEFISIT","AMAN"))) -> SURPLUS
A6: 3 | B6: =IF(Pengaturan!$B$3+14>Pengaturan!$B$4,"",TEXT(Pengaturan!$B$3+14,"dd mmm")&" - "&TEXT(MIN(Pengaturan!$B$3+20,Pengaturan!$B$4),"dd mmm")) | C6: =SUMIF('Rekap Harian'!$D$6:$D$36,A6,'Rekap Harian'!$E$6:$E$36) -> 0 | D6: =SUMIF('Rekap Harian'!$D$6:$D$36,A6,'Rekap Harian'!$F$6:$F$36) -> 0 | E6: =C6-D6 -> 0 | F6: =SUMIF('Rekap Harian'!$D$6:$D$36,A6,'Rekap Harian'!$H$6:$H$36) -> 0 | G6: =SUMIF('Rekap Harian'!$D$6:$D$36,A6,'Rekap Harian'!$I$6:$I$36) -> 0 | H6: =F6-G6 -> 0 | I6: =C6+F6 -> 0 | J6: =D6+G6 -> 0 | K6: =I6-J6 -> 0 | L6: =IF(I6=0,"",IF(K6>0,"SURPLUS",IF(K6<0,"DEFISIT","AMAN")))
A7: 4 | B7: =IF(Pengaturan!$B$3+21>Pengaturan!$B$4,"",TEXT(Pengaturan!$B$3+21,"dd mmm")&" - "&TEXT(MIN(Pengaturan!$B$3+27,Pengaturan!$B$4),"dd mmm")) | C7: =SUMIF('Rekap Harian'!$D$6:$D$36,A7,'Rekap Harian'!$E$6:$E$36) -> 0 | D7: =SUMIF('Rekap Harian'!$D$6:$D$36,A7,'Rekap Harian'!$F$6:$F$36) -> 0 | E7: =C7-D7 -> 0 | F7: =SUMIF('Rekap Harian'!$D$6:$D$36,A7,'Rekap Harian'!$H$6:$H$36) -> 0 | G7: =SUMIF('Rekap Harian'!$D$6:$D$36,A7,'Rekap Harian'!$I$6:$I$36) -> 0 | H7: =F7-G7 -> 0 | I7: =C7+F7 -> 0 | J7: =D7+G7 -> 0 | K7: =I7-J7 -> 0 | L7: =IF(I7=0,"",IF(K7>0,"SURPLUS",IF(K7<0,"DEFISIT","AMAN")))
A8: 5 | B8: =IF(Pengaturan!$B$3+28>Pengaturan!$B$4,"",TEXT(Pengaturan!$B$3+28,"dd mmm")&" - "&TEXT(MIN(Pengaturan!$B$3+34,Pengaturan!$B$4),"dd mmm")) | C8: =SUMIF('Rekap Harian'!$D$6:$D$36,A8,'Rekap Harian'!$E$6:$E$36) -> 0 | D8: =SUMIF('Rekap Harian'!$D$6:$D$36,A8,'Rekap Harian'!$F$6:$F$36) -> 0 | E8: =C8-D8 -> 0 | F8: =SUMIF('Rekap Harian'!$D$6:$D$36,A8,'Rekap Harian'!$H$6:$H$36) -> 0 | G8: =SUMIF('Rekap Harian'!$D$6:$D$36,A8,'Rekap Harian'!$I$6:$I$36) -> 0 | H8: =F8-G8 -> 0 | I8: =C8+F8 -> 0 | J8: =D8+G8 -> 0 | K8: =I8-J8 -> 0 | L8: =IF(I8=0,"",IF(K8>0,"SURPLUS",IF(K8<0,"DEFISIT","AMAN")))
A10: TOTAL | C10: =SUM(C4:C8) -> 254106000 | D10: =SUM(D4:D8) -> 221393431 | E10: =SUM(E4:E8) -> 32712569 | F10: =SUM(F4:F8) -> 112747500 | G10: =SUM(G4:G8) -> 120676500 | H10: =SUM(H4:H8) -> -7929000 | I10: =SUM(I4:I8) -> 366853500 | J10: =SUM(J4:J8) -> 342069931 | K10: =SUM(K4:K8) -> 24783569

Sheet Grafik
A1: VISUALISASI LAPORAN KEUANGAN
A2: Grafik profesional di sebelah kanan tabel data
A4: 1. Tren Harian - Pangan & Operasional vs Pagu
A5: Tgl | B5: Aktual Pangan | C5: Pagu Pangan | D5: Aktual Operasional | E5: Pagu Operasional
A6: ='Rekap Harian'!B6 -> 45901 | B6: ='Rekap Harian'!F6 -> 31728300 | C6: ='Rekap Harian'!E6 -> 28234000 | D6: ='Rekap Harian'!I6 -> 11376000 | E6: ='Rekap Harian'!H6 -> 12527500
A7: ='Rekap Harian'!B7 -> 45902 | B7: ='Rekap Harian'!F7 -> 29861200 | C7: ='Rekap Harian'!E7 -> 28234000 | D7: ='Rekap Harian'!I7 -> 1033500 | E7: ='Rekap Harian'!H7 -> 12527500
A8: ='Rekap Harian'!B8 -> 45903 | B8: ='Rekap Harian'!F8 -> 27381000 | C8: ='Rekap Harian'!E8 -> 28234000 | D8: ='Rekap Harian'!I8 -> 2768000 | E8: ='Rekap Harian'!H8 -> 12527500
A9: ='Rekap Harian'!B9 -> 45904 | B9: ='Rekap Harian'!F9 -> 20791000 | C9: ='Rekap Harian'!E9 -> 28234000 | D9: ='Rekap Harian'!I9 -> 18250000 | E9: ='Rekap Harian'!H9 -> 12527500
A10: ='Rekap Harian'!B10 -> 45905 | B10: ='Rekap Harian'!F10 -> 0 | C10: ='Rekap Harian'!E10 -> 0 | D10: ='Rekap Harian'!I10 -> 0 | E10: ='Rekap Harian'!H10 -> 0
A11: ='Rekap Harian'!B11 -> 45906 | B11: ='Rekap Harian'!F11 -> 0 | C11: ='Rekap Harian'!E11 -> 0 | D11: ='Rekap Harian'!I11 -> 0 | E11: ='Rekap Harian'!H11 -> 0
A12: ='Rekap Harian'!B12 -> 45907 | B12: ='Rekap Harian'!F12 -> 0 | C12: ='Rekap Harian'!E12 -> 0 | D12: ='Rekap Harian'!I12 -> 0 | E12: ='Rekap Harian'!H12 -> 0
A13: ='Rekap Harian'!B13 -> 45908 | B13: ='Rekap Harian'!F13 -> 23935050 | C13: ='Rekap Harian'!E13 -> 28234000 | D13: ='Rekap Harian'!I13 -> 5534000 | E13: ='Rekap Harian'!H13 -> 12527500
A14: ='Rekap Harian'!B14 -> 45909 | B14: ='Rekap Harian'!F14 -> 22762300 | C14: ='Rekap Harian'!E14 -> 28234000 | D14: ='Rekap Harian'!I14 -> 0 | E14: ='Rekap Harian'!H14 -> 12527500
A15: ='Rekap Harian'!B15 -> 45910 | B15: ='Rekap Harian'!F15 -> 16132300 | C15: ='Rekap Harian'!E15 -> 28234000 | D15: ='Rekap Harian'!I15 -> 1820000 | E15: ='Rekap Harian'!H15 -> 12527500
A16: ='Rekap Harian'!B16 -> 45911 | B16: ='Rekap Harian'!F16 -> 23274600 | C16: ='Rekap Harian'!E16 -> 28234000 | D16: ='Rekap Harian'!I16 -> 2396500 | E16: ='Rekap Harian'!H16 -> 12527500
A17: ='Rekap Harian'!B17 -> 45912 | B17: ='Rekap Harian'!F17 -> 25527681 | C17: ='Rekap Harian'!E17 -> 28234000 | D17: ='Rekap Harian'!I17 -> 77498500 | E17: ='Rekap Harian'!H17 -> 12527500
... A36: ='Rekap Harian'!B36 | B36: ='Rekap Harian'!F36 -> 0 | C36: ='Rekap Harian'!E36 | D36: ='Rekap Harian'!I36 -> 0 | E36: ='Rekap Harian'!H36
A38: 2. Surplus vs Defisit Per Hari
A39: Tgl | B39: Surplus (Rp) | C39: Defisit (Rp)
A40: ='Rekap Harian'!B6 -> 45901 | B40: =IF('Rekap Harian'!M6>0,'Rekap Harian'!M6,0) -> 0 | C40: =IF('Rekap Harian'!M6<0,-'Rekap Harian'!M6,0) -> 2342800
A41: ='Rekap Harian'!B7 -> 45902 | B41: =IF('Rekap Harian'!M7>0,'Rekap Harian'!M7,0) -> 9866800 | C41: =IF('Rekap Harian'!M7<0,-'Rekap Harian'!M7,0) -> 0
A42: ='Rekap Harian'!B8 -> 45903 | B42: =IF('Rekap Harian'!M8>0,'Rekap Harian'!M8,0) -> 10612500 | C42: =IF('Rekap Harian'!M8<0,-'Rekap Harian'!M8,0) -> 0
A43: ='Rekap Harian'!B9 -> 45904 | B43: =IF('Rekap Harian'!M9>0,'Rekap Harian'!M9,0) -> 1720500 | C43: =IF('Rekap Harian'!M9<0,-'Rekap Harian'!M9,0) -> 0
A44: ='Rekap Harian'!B10 -> 45905 | B44: =IF('Rekap Harian'!M10>0,'Rekap Harian'!M10,0) -> 0 | C44: =IF('Rekap Harian'!M10<0,-'Rekap Harian'!M10,0) -> 0
A45: ='Rekap Harian'!B11 -> 45906 | B45: =IF('Rekap Harian'!M11>0,'Rekap Harian'!M11,0) -> 0 | C45: =IF('Rekap Harian'!M11<0,-'Rekap Harian'!M11,0) -> 0
A46: ='Rekap Harian'!B12 -> 45907 | B46: =IF('Rekap Harian'!M12>0,'Rekap Harian'!M12,0) -> 0 | C46: =IF('Rekap Harian'!M12<0,-'Rekap Harian'!M12,0) -> 0
A47: ='Rekap Harian'!B13 -> 45908 | B47: =IF('Rekap Harian'!M13>0,'Rekap Harian'!M13,0) -> 11292450 | C47: =IF('Rekap Harian'!M13<0,-'Rekap Harian'!M13,0) -> 0
A48: ='Rekap Harian'!B14 -> 45909 | B48: =IF('Rekap Harian'!M14>0,'Rekap Harian'!M14,0) -> 17999200 | C48: =IF('Rekap Harian'!M14<0,-'Rekap Harian'!M14,0) -> 0
A49: ='Rekap Harian'!B15 -> 45910 | B49: =IF('Rekap Harian'!M15>0,'Rekap Harian'!M15,0) -> 22809200 | C49: =IF('Rekap Harian'!M15<0,-'Rekap Harian'!M15,0) -> 0
A50: ='Rekap Harian'!B16 -> 45911 | B50: =IF('Rekap Harian'!M16>0,'Rekap Harian'!M16,0) -> 15090400 | C50: =IF('Rekap Harian'!M16<0,-'Rekap Harian'!M16,0) -> 0
A51: ='Rekap Harian'!B17 -> 45912 | B51: =IF('Rekap Harian'!M17>0,'Rekap Harian'!M17,0) -> 0 | C51: =IF('Rekap Harian'!M17<0,-'Rekap Harian'!M17,0) -> 62264681
... A70: ='Rekap Harian'!B36 | B70: =IF('Rekap Harian'!M36>0,'Rekap Harian'!M36,0) -> #VALUE! | C70: =IF('Rekap Harian'!M36<0,-'Rekap Harian'!M36,0) -> #VALUE!
A72: 3. Rekap Mingguan - Aktual vs Pagu
A73: Minggu | B73: Aktual Pangan | C73: Pagu Pangan | D73: Aktual Operasional | E73: Pagu Operasional
A74: ="Mg "&A4 -> Mg 1. Tren Harian - Pangan & Operasional vs Pagu | B74: ='Rekap Mingguan'!D4 -> 109761500 | C74: ='Rekap Mingguan'!C4 -> 112936000 | D74: ='Rekap Mingguan'!G4 -> 33427500 | E74: ='Rekap Mingguan'!F4 -> 50110000
A75: ="Mg "&A5 -> Mg Tgl | B75: ='Rekap Mingguan'!D5 -> 111631931 | C75: ='Rekap Mingguan'!C5 -> 141170000 | D75: ='Rekap Mingguan'!G5 -> 87249000 | E75: ='Rekap Mingguan'!F5 -> 62637500
A76: ="Mg "&A6 -> Mg 45901 | B76: ='Rekap Mingguan'!D6 -> 0 | C76: ='Rekap Mingguan'!C6 -> 0 | D76: ='Rekap Mingguan'!G6 -> 0 | E76: ='Rekap Mingguan'!F6 -> 0
A77: ="Mg "&A7 -> Mg 45902 | B77: ='Rekap Mingguan'!D7 -> 0 | C77: ='Rekap Mingguan'!C7 -> 0 | D77: ='Rekap Mingguan'!G7 -> 0 | E77: ='Rekap Mingguan'!F7 -> 0
A78: ="Mg "&A8 -> Mg 45903 | B78: ='Rekap Mingguan'!D8 -> 0 | C78: ='Rekap Mingguan'!C8 -> 0 | D78: ='Rekap Mingguan'!G8 -> 0 | E78: ='Rekap Mingguan'!F8 -> 0
A80: 4. Komposisi Pengeluaran
...

Sheet Pengaturan
A1: PENGATURAN LAPORAN KEUANGAN
A2: Master konfigurasi - edit bagian ini untuk menyesuaikan laporan
A3: Periode Mulai | B3: 45901 | C3: <- edit tanggal
A4: Periode Selesai | B4: 45912 | C4: <- edit tanggal
A5: Jumlah Hari Operasi | B5: =B4-B3+1 -> 12 | C5: (otomatis)
A7: DANA ANGGARAN
A8: Dana Total Bahan Pangan | B8: 282340000 | C8: <- edit total dana
A9: Dana Total Operasional | B9: =90330000+60000000 -> 150330000 | C9: <- edit total dana
A10: Total Dana Keseluruhan | B10: =B8+B9 -> 432670000
A12: PAGU DEFAULT / HARI (SEHARUSNYA)
A13: Pagu Default Pangan/Hari | B13: 28234000 | C13: = Dana Pangan / Jumlah Hari
A14: Pagu Default Operasional/Hari | B14: 12527500 | C14: = Dana Operasional / Jumlah Hari
A15: Pagu Default Total/Hari | B15: =SUM(B13:B14) -> 40761500 | C15: = Pangan + Operasional
A17: INFORMASI ORGANISASI
A18: Nama Instansi | B18: SPPG Battuwinangun
A19: Alamat | B19: -
A20: Penanggung Jawab | B20: Alfiansah Prastyo, S.Kel
A21: Periode Laporan | B21: =TEXT(B3,"dd mmm yyyy")&" s/d "&TEXT(B4,"dd mmm yyyy") -> 01 Sep 2025 s/d 12 Sep 2025
A23: CATATAN:
A24: - Edit hanya di kolom B pada baris yang bertanda <- edit
A25: - Pagu per hari bisa berbeda-beda, diatur di sheet 'Pagu Harian'
A26: - Isi aktual pangan & operasional langsung di sheet 'Rekap Harian'
A27: - Dashboard, Rekap Mingguan, & Grafik update otomatis

Sheet Pagu Harian
A1: PAGU HARIAN PENGELUARAN
A2: Set pagu per tanggal. Biarkan default jika pagu hari itu sama dengan Pengaturan
A3: Tanggal | B3: Pagu Pangan (Rp) | C3: Pagu Operasional (Rp) | D3: Pagu Total (Rp) | E3: Keterangan
A4: =IF(Pengaturan!$B$3+0>Pengaturan!$B$4,"",Pengaturan!$B$3+0) -> 45901 | B4: 28234000 | C4: 12527500 | D4: =IF(A4="","",B4+C4) -> 40761500
A5: =IF(Pengaturan!$B$3+1>Pengaturan!$B$4,"",Pengaturan!$B$3+1) -> 45902 | B5: 28234000 | C5: 12527500 | D5: =IF(A5="","",B5+C5) -> 40761500
A6: =IF(Pengaturan!$B$3+2>Pengaturan!$B$4,"",Pengaturan!$B$3+2) -> 45903 | B6: 28234000 | C6: 12527500 | D6: =IF(A6="","",B6+C6) -> 40761500
A7: =IF(Pengaturan!$B$3+3>Pengaturan!$B$4,"",Pengaturan!$B$3+3) -> 45904 | B7: 28234000 | C7: 12527500 | D7: =IF(A7="","",B7+C7) -> 40761500
A8: =IF(Pengaturan!$B$3+4>Pengaturan!$B$4,"",Pengaturan!$B$3+4) -> 45905 | B8: 28234000 | C8: 12527500 | D8: =IF(A8="","",B8+C8) -> 40761500
A9: =IF(Pengaturan!$B$3+5>Pengaturan!$B$4,"",Pengaturan!$B$3+5) -> 45906 | B9: 28234000 | C9: 12527500 | D9: =IF(A9="","",B9+C9) -> 40761500
A10: =IF(Pengaturan!$B$3+6>Pengaturan!$B$4,"",Pengaturan!$B$3+6) -> 45907 | B10: 28234000 | C10: 12527500 | D10: =IF(A10="","",B10+C10) -> 40761500
A11: =IF(Pengaturan!$B$3+7>Pengaturan!$B$4,"",Pengaturan!$B$3+7) -> 45908 | B11: 28234000 | C11: 12527500 | D11: =IF(A11="","",B11+C11) -> 40761500
A12: =IF(Pengaturan!$B$3+8>Pengaturan!$B$4,"",Pengaturan!$B$3+8) -> 45909 | B12: 28234000 | C12: 12527500 | D12: =IF(A12="","",B12+C12) -> 40761500
A13: =IF(Pengaturan!$B$3+9>Pengaturan!$B$4,"",Pengaturan!$B$3+9) -> 45910 | B13: 28234000 | C13: 12527500 | D13: =IF(A13="","",B13+C13) -> 40761500
A14: =IF(Pengaturan!$B$3+10>Pengaturan!$B$4,"",Pengaturan!$B$3+10) -> 45911 | B14: 28234000 | C14: 12527500 | D14: =IF(A14="","",B14+C14) -> 40761500
A15: =IF(Pengaturan!$B$3+11>Pengaturan!$B$4,"",Pengaturan!$B$3+11) -> 45912 | B15: 28234000 | C15: 12527500 | D15: =IF(A15="","",B15+C15) -> 40761500
A16: =IF(Pengaturan!$B$3+12>Pengaturan!$B$4,"",Pengaturan!$B$3+12) | B16: =IF(A16="","",Pengaturan!$B$13) | C16: =IF(A16="","",Pengaturan!$B$14) | D16: =IF(A16="","",B16+C16)
A17: =IF(Pengaturan!$B$3+13>Pengaturan!$B$4,"",Pengaturan!$B$3+13) | B17: =IF(A17="","",Pengaturan!$B$13) | C17: =IF(A17="","",Pengaturan!$B$14) | D17: =IF(A17="","",B17+C17)
A18: =IF(Pengaturan!$B$3+14>Pengaturan!$B$4,"",Pengaturan!$B$3+14) | B18: =IF(A18="","",Pengaturan!$B$13) | C18: =IF(A18="","",Pengaturan!$B$14) | D18: =IF(A18="","",B18+C18)
A19: =IF(Pengaturan!$B$3+15>Pengaturan!$B$4,"",Pengaturan!$B$3+15) | B19: =IF(A19="","",Pengaturan!$B$13) | C19: =IF(A19="","",Pengaturan!$B$14) | D19: =IF(A19="","",B19+C19)
A20: =IF(Pengaturan!$B$3+16>Pengaturan!$B$4,"",Pengaturan!$B$3+16) | B20: =IF(A20="","",Pengaturan!$B$13) | C20: =IF(A20="","",Pengaturan!$B$14) | D20: =IF(A20="","",B20+C20)
A21: =IF(Pengaturan!$B$3+17>Pengaturan!$B$4,"",Pengaturan!$B$3+17) | B21: =IF(A21="","",Pengaturan!$B$13) | C21: =IF(A21="","",Pengaturan!$B$14) | D21: =IF(A21="","",B21+C21)
A22: =IF(Pengaturan!$B$3+18>Pengaturan!$B$4,"",Pengaturan!$B$3+18) | B22: =IF(A22="","",Pengaturan!$B$13) | C22: =IF(A22="","",Pengaturan!$B$14) | D22: =IF(A22="","",B22+C22)
A23: =IF(Pengaturan!$B$3+19>Pengaturan!$B$4,"",Pengaturan!$B$3+19) | B23: =IF(A23="","",Pengaturan!$B$13) | C23: =IF(A23="","",Pengaturan!$B$14) | D23: =IF(A23="","",B23+C23)
A24: =IF(Pengaturan!$B$3+20>Pengaturan!$B$4,"",Pengaturan!$B$3+20) | B24: =IF(A24="","",Pengaturan!$B$13) | C24: =IF(A24="","",Pengaturan!$B$14) | D24: =IF(A24="","",B24+C24)
A25: =IF(Pengaturan!$B$3+21>Pengaturan!$B$4,"",Pengaturan!$B$3+21) | B25: =IF(A25="","",Pengaturan!$B$13) | C25: =IF(A25="","",Pengaturan!$B$14) | D25: =IF(A25="","",B25+C25)
A26: =IF(Pengaturan!$B$3+22>Pengaturan!$B$4,"",Pengaturan!$B$3+22) | B26: =IF(A26="","",Pengaturan!$B$13) | C26: =IF(A26="","",Pengaturan!$B$14) | D26: =IF(A26="","",B26+C26)
A27: =IF(Pengaturan!$B$3+23>Pengaturan!$B$4,"",Pengaturan!$B$3+23) | B27: =IF(A27="","",Pengaturan!$B$13) | C27: =IF(A27="","",Pengaturan!$B$14) | D27: =IF(A27="","",B27+C27)
A28: =IF(Pengaturan!$B$3+24>Pengaturan!$B$4,"",Pengaturan!$B$3+24) | B28: =IF(A28="","",Pengaturan!$B$13) | C28: =IF(A28="","",Pengaturan!$B$14) | D28: =IF(A28="","",B28+C28)
A29: =IF(Pengaturan!$B$3+25>Pengaturan!$B$4,"",Pengaturan!$B$3+25) | B29: =IF(A29="","",Pengaturan!$B$13) | C29: =IF(A29="","",Pengaturan!$B$14) | D29: =IF(A29="","",B29+C29)
A30: =IF(Pengaturan!$B$3+26>Pengaturan!$B$4,"",Pengaturan!$B$3+26) | B30: =IF(A30="","",Pengaturan!$B$13) | C30: =IF(A30="","",Pengaturan!$B$14) | D30: =IF(A30="","",B30+C30)
A31: =IF(Pengaturan!$B$3+27>Pengaturan!$B$4,"",Pengaturan!$B$3+27) | B31: =IF(A31="","",Pengaturan!$B$13) | C31: =IF(A31="","",Pengaturan!$B$14) | D31: =IF(A31="","",B31+C31)
A32: =IF(Pengaturan!$B$3+28>Pengaturan!$B$4,"",Pengaturan!$B$3+28) | B32: =IF(A32="","",Pengaturan!$B$13) | C32: =IF(A32="","",Pengaturan!$B$14) | D32: =IF(A32="","",B32+C32)
A33: =IF(Pengaturan!$B$3+29>Pengaturan!$B$4,"",Pengaturan!$B$3+29) | B33: =IF(A33="","",Pengaturan!$B$13) | C33: =IF(A33="","",Pengaturan!$B$14) | D33: =IF(A33="","",B33+C33)
A34: =IF(Pengaturan!$B$3+30>Pengaturan!$B$4,"",Pengaturan!$B$3+30) | B34: =IF(A34="","",Pengaturan!$B$13) | C34: =IF(A34="","",Pengaturan!$B$14) | D34: =IF(A34="","",B34+C34)
A36: TOTAL | B36: =SUM(B4:B34) -> 338808000 | C36: =SUM(C4:C34) -> 150330000 | D36: =SUM(D4:D34) -> 489138000

Sheet Kategori
A1: DAFTAR KATEGORI (REFERENSI)
A2: Referensi daftar kategori - tidak dipakai di formula, hanya panduan
A3: Kategori Bahan Pangan | B3: Kategori Operasional
A4: Karbohidrat | B4: Bahan Bakar
A5: Protein Hewani | B5: Tenaga Kerja
A6: Protein Nabati | B6: Utilitas
A7: Sayuran | B7: Sanitasi
A8: Buah | B8: Packaging
A9: Susu & Olahan | B9: Transportasi
A10: Bumbu | B10: Peralatan
A11: Minuman | B11: Pemeliharaan
A12: Lain-lain | B12: Administrasi
B13: Lain-lain
